<mujoco model="humanoid">
  <compiler angle="radian"/>

  <option timestep="0.00222222" integrator="implicitfast"/>

  <visual>
    <global offwidth="1280" offheight="960"/>
    <headlight ambient="0.34 0.34 0.34" diffuse="0.5 0.5 0.5"/>
  </visual>

  <default>
    <joint solimplimit="0 0.99 0.01" stiffness="2" limited="true" armature="0.01" damping="2"/>
    <geom condim="1" friction="0.7" solref="0.015" solimp="0.99 0.99 0.003" margin="0.001" rgba="0.8 0.6 0.4 1"/>
    <default class="smplcontact">
      <geom condim="3" priority="1" friction="1" solimp="0.98 0.98 0.001"/>
    </default>
    <default class="stiff_medium">
      <joint stiffness="10"/>
    </default>
    <default class="stiff_medium_higher">
      <joint stiffness="50"/>
    </default>
    <default class="stiff_high">
      <joint stiffness="100"/>
    </default>
  </default>

  <asset>
    <texture type="skybox" colorspace="auto" builtin="gradient" rgb1="0.99 0.99 0.99" rgb2="0.608 0.828 0.892" width="100" height="600"/>
    <texture type="cube" colorspace="auto" name="texgeom" builtin="flat" mark="cross" rgb1="0.8 0.6 0.4" rgb2="0.8 0.6 0.4" markrgb="1 1 1" width="127" height="762"/>
    <texture type="2d" colorspace="auto" name="texplane" builtin="checker" rgb1="0.756 0.772 0.76" rgb2="0.6 0.6 0.6" markrgb="1 1 1" width="100" height="100"/>
    <material name="MatPlane" texture="texplane" texuniform="true" reflectance="0.5"/>
    <material name="geom" texture="texgeom" texuniform="true"/>
  </asset>

  <worldbody>
    <geom name="floor" size="100 100 0.2" type="plane" condim="3" material="MatPlane" rgba="1 1 1 1"/>
    <camera name="back" pos="0 3 2.4" quat="0 0 0.525731 0.850651" mode="trackcom"/>
    <camera name="side" pos="-3 0 2.4" quat="0.601501 0.371748 -0.371748 -0.601501" mode="trackcom"/>
    <camera name="front_side" pos="-2.8 -2.8 0.8" quat="0.697522 0.605818 -0.250938 -0.288923" mode="trackcom"/>
    <light name="tracking_light" pos="0 0 7" dir="0 0 -1" type="directional" cutoff="100" exponent="1" diffuse="1 1 1" specular="0.1 0.1 0.1" mode="trackcom"/>
    <body name="Pelvis" pos="-0.0018 -0.2233 0.0282">
      <joint name="Pelvis" type="free" solimplimit="0.9 0.95 0.001" stiffness="0" armature="0" damping="0"/>
      <geom name="Pelvis" size="0.1069 0.0722 0.083" pos="0 -0.0121 -0.0055" type="box" density="3165.83"/>
      <site name="Pelvis" pos="0 0 0" size="0.01"/>
      <body name="L_Hip" pos="0.0695 -0.0914 -0.0068">
        <joint name="L_Hip_x" class="stiff_medium" pos="0 0 0" axis="1 0 0" range="-2.79253 0.400029" damping="15"/>
        <joint name="L_Hip_y" class="stiff_medium" pos="0 0 0" axis="0 1 0" range="-1.22173 1.22173" damping="10"/>
        <joint name="L_Hip_z" class="stiff_medium" pos="0 0 0" axis="0 0 1" range="-0.500037 1.5708" damping="10"/>
        <geom name="L_Hip" size="0.0615 0.113074" pos="0.01715 -0.1876 -0.00225" quat="0.711315 -0.699979 -0.0637192 0" type="capsule" density="2040.82"/>
        <body name="L_Knee" pos="0.0343 -0.3752 -0.0045">
          <joint name="L_Knee_x" pos="0 0 0" axis="1 0 0" range="-0.090059 3.00005" damping="8"/>
          <joint name="L_Knee_y" pos="0 0 0" axis="0 1 0" range="-0.0799361 0.120079" damping="8"/>
          <joint name="L_Knee_z" pos="0 0 0" axis="0 0 1" range="-0.120079 0.0799361" damping="8"/>
          <geom name="L_Knee" size="0.0541 0.120192" pos="-0.0068 -0.199 -0.02185" quat="0.744785 -0.666912 0.0229007 0" type="capsule" density="1234.57"/>
          <body name="L_Ankle" pos="-0.0136 -0.398 -0.0437">
            <joint name="L_Ankle_x" class="stiff_medium" pos="0 0 0" axis="1 0 0" range="-0.800059 0.800059" damping="6"/>
            <joint name="L_Ankle_y" class="stiff_medium" pos="0 0 0" axis="0 1 0" range="-1.29992 0.400029" damping="3"/>
            <joint name="L_Ankle_z" class="stiff_medium" pos="0 0 0" axis="0 0 1" range="-0.0799361 0.0799361" damping="6"/>
            <geom name="L_Ankle" class="smplcontact" size="0.0483 0.0464 0.085" pos="0.0233 -0.0239 0.0242" type="box" density="449.072"/>
            <body name="L_Toe" pos="0.0264 -0.0558 0.1193">
              <joint name="L_Toe_x" pos="0 0 0" axis="1 0 0" range="-1.59994 0.400029"/>
              <joint name="L_Toe_y" pos="0 0 0" axis="0 1 0" range="-0.0799361 0.0799361"/>
              <joint name="L_Toe_z" pos="0 0 0" axis="0 0 1" range="-0.0799361 0.0799361"/>
              <geom name="L_Toe" class="smplcontact" size="0.0478 0.02 0.0496" pos="-0.003 0.0055 0.0248" type="box" density="423.207"/>
            </body>
          </body>
        </body>
      </body>
      <body name="R_Hip" pos="-0.0677 -0.0905 -0.0043">
        <joint name="R_Hip_x" class="stiff_medium" pos="0 0 0" axis="1 0 0" range="-2.79253 0.400029" damping="15"/>
        <joint name="R_Hip_y" class="stiff_medium" pos="0 0 0" axis="0 1 0" range="-1.22173 1.22173" damping="10"/>
        <joint name="R_Hip_z" class="stiff_medium" pos="0 0 0" axis="0 0 1" range="-1.5708 0.500037" damping="10"/>
        <geom name="R_Hip" size="0.0606 0.1154" pos="-0.01915 -0.1913 -0.00445" quat="0.71518 -0.69549 0.0693673 0" type="capsule" density="2040.82"/>
        <body name="R_Knee" pos="-0.0383 -0.3826 -0.0089">
          <joint name="R_Knee_x" pos="0 0 0" axis="1 0 0" range="-0.090059 3.00005" damping="8"/>
          <joint name="R_Knee_y" pos="0 0 0" axis="0 1 0" range="-0.120079 0.0799361" damping="8"/>
          <joint name="R_Knee_z" pos="0 0 0" axis="0 0 1" range="-0.0799361 0.120079" damping="8"/>
          <geom name="R_Knee" size="0.0541 0.12026" pos="0.0079 -0.1992 -0.02115" quat="0.743367 -0.668367 -0.0262872 0" type="capsule" density="1234.57"/>
          <body name="R_Ankle" pos="0.0158 -0.3984 -0.0423">
            <joint name="R_Ankle_x" class="stiff_medium" pos="0 0 0" axis="1 0 0" range="-0.800059 0.800059" damping="6"/>
            <joint name="R_Ankle_y" class="stiff_medium" pos="0 0 0" axis="0 1 0" range="-0.400029 1.29992" damping="3"/>
            <joint name="R_Ankle_z" class="stiff_medium" pos="0 0 0" axis="0 0 1" range="-0.0799361 0.0799361" damping="6"/>
            <geom name="R_Ankle" class="smplcontact" size="0.0483 0.0478 0.0865" pos="-0.0212 -0.0174 0.0256" type="box" density="434.701"/>
            <body name="R_Toe" pos="-0.0254 -0.0481 0.1233">
              <joint name="R_Toe_x" pos="0 0 0" axis="1 0 0" range="-1.59994 0.400029"/>
              <joint name="R_Toe_y" pos="0 0 0" axis="0 1 0" range="-0.0799361 0.0799361"/>
              <joint name="R_Toe_z" pos="0 0 0" axis="0 0 1" range="-0.0799361 0.0799361"/>
              <geom name="R_Toe" class="smplcontact" size="0.0479 0.0216 0.0493" pos="0.0042 0.0045 0.0227" type="box" density="407.384"/>
            </body>
          </body>
        </body>
      </body>
      <body name="Torso" pos="-0.0025 0.109 -0.0267">
        <joint name="Torso_x" class="stiff_medium" pos="0 0 0" axis="1 0 0" range="-0.449946 1.00007" damping="15"/>
        <joint name="Torso_y" class="stiff_high" pos="0 0 0" axis="0 1 0" range="-1.00007 1.00007" damping="20"/>
        <joint name="Torso_z" class="stiff_high" pos="0 0 0" axis="0 0 1" range="-0.600044 0.600044" damping="20"/>
        <geom name="Torso" size="0.0769 0.00675481" pos="0.00275 0.06755 0.00055" quat="0.704485 0.709233 -0.0262679 0" type="capsule" density="2040.82"/>
        <body name="Spine" pos="0.0055 0.1352 0.0011">
          <joint name="Spine_x" class="stiff_medium" pos="0 0 0" axis="1 0 0" range="-0.449946 1.00007" damping="15"/>
          <joint name="Spine_y" class="stiff_high" pos="0 0 0" axis="0 1 0" stiffness="10" range="-1.00007 1.00007" damping="8"/>
          <joint name="Spine_z" class="stiff_high" pos="0 0 0" axis="0 0 1" stiffness="20" range="-0.600044 0.600044" damping="12"/>
          <geom name="Spine" size="0.0755 0.00295212" pos="0.00075 0.02645 0.0127" quat="0.528979 0.848484 -0.0160091 0" type="capsule" density="2040.82"/>
          <body name="Chest" pos="0.0015 0.0529 0.0254">
            <joint name="Chest_x" class="stiff_medium" pos="0 0 0" axis="1 0 0" range="-0.449946 1.00007" damping="15"/>
            <joint name="Chest_y" class="stiff_high" pos="0 0 0" axis="0 1 0" stiffness="10" range="-1.00007 1.00007" damping="8"/>
            <joint name="Chest_z" class="stiff_high" pos="0 0 0" axis="0 0 1" stiffness="20" range="-0.600044 0.600044" damping="12"/>
            <geom name="Chest" size="0.1002 0.00779792" pos="-0.00095 0.07575 -0.01925" quat="0.790591 0.612332 0.00405518 0" type="capsule" density="2040.82"/>
            <body name="Neck" pos="-0.0028 0.2139 -0.0429">
              <joint name="Neck_x" class="stiff_medium_higher" pos="0 0 0" axis="1 0 0" range="-0.500037 1.00007" damping="10"/>
              <joint name="Neck_y" class="stiff_medium_higher" pos="0 0 0" axis="0 1 0" range="-0.700052 0.700052" damping="10"/>
              <joint name="Neck_z" class="stiff_medium_higher" pos="0 0 0" axis="0 0 1" range="-0.700052 0.700052" damping="10"/>
              <geom name="Neck" size="0.0436 0.024896" pos="0.00255 0.0325 0.0257" quat="0.436708 0.896775 -0.0712821 0" type="capsule"/>
              <body name="Head" pos="0.0052 0.065 0.0513">
                <joint name="Head_x" class="stiff_medium_higher" pos="0 0 0" axis="1 0 0" range="-0.500037 1.00007"/>
                <joint name="Head_y" class="stiff_medium_higher" pos="0 0 0" axis="0 1 0" range="-0.700052 0.700052"/>
                <joint name="Head_z" class="stiff_medium_higher" pos="0 0 0" axis="0 0 1" range="-0.700052 0.700052"/>
                <geom name="Head" size="0.0606 0.1154 0.076" pos="-0.0042 0.0876 -0.0116" type="box" density="1018.07"/>
                <geom name="nose" size="0.02 0.01" pos="0 0.07 0.05" type="capsule" contype="0" conaffinity="0" mass="0"/>
              </body>
            </body>
            <body name="L_Thorax" pos="0.0788 0.1217 -0.0341">
              <joint name="L_Thorax_x" class="stiff_medium_higher" pos="0 0 0" axis="1 0 0" range="-0.190066 0.0799361" damping="20"/>
              <joint name="L_Thorax_y" class="stiff_medium_higher" pos="0 0 0" axis="0 1 0" range="-0.500037 0.300022" damping="20"/>
              <joint name="L_Thorax_z" class="stiff_medium_higher" pos="0 0 0" axis="0 0 1" range="-0.549953 0.700052" damping="20"/>
              <geom name="L_Thorax" size="0.0521 0.0289143" pos="0.0455 0.01525 -0.00445" quat="0.7388 0.214167 -0.638989 0" type="capsule"/>
              <body name="L_Shoulder" pos="0.091 0.0305 -0.0089">
                <joint name="L_Shoulder_x" class="stiff_medium" pos="0 0 0" axis="1 0 0" range="-1.69995 1.69995" damping="6"/>
                <joint name="L_Shoulder_y" class="stiff_medium" pos="0 0 0" axis="0 1 0" range="-1.89997 1.39993" damping="6"/>
                <joint name="L_Shoulder_z" class="stiff_medium" pos="0 0 0" axis="0 0 1" range="-1.69995 1.49994" damping="6"/>
                <geom name="L_Shoulder" size="0.0517 0.0784278" pos="0.1298 -0.0064 -0.01375" quat="0.743368 -0.0325897 -0.668088 0" type="capsule"/>
                <body name="L_Elbow" pos="0.2596 -0.0128 -0.0275">
                  <joint name="L_Elbow_x" pos="0 0 0" axis="1 0 0" range="-0.300022 0.0799361" damping="5"/>
                  <joint name="L_Elbow_y" pos="0 0 0" axis="0 1 0" range="-3.14159 0.300022" damping="5"/>
                  <joint name="L_Elbow_z" pos="0 0 0" axis="0 0 1" range="-1.75999 0.0799361" damping="5"/>
                  <geom name="L_Elbow" size="0.0405 0.0748495" pos="0.1246 0.0045 -0.00055" quat="0.708758 0.0254476 -0.704992 0" type="capsule"/>
                  <body name="L_Wrist" pos="0.2492 0.009 -0.0012">
                    <joint name="L_Wrist_x" pos="0 0 0" axis="1 0 0" range="-3.14159 0.400029"/>
                    <joint name="L_Wrist_y" pos="0 0 0" axis="0 1 0" range="-0.300022 0.300022"/>
                    <joint name="L_Wrist_z" pos="0 0 0" axis="0 0 1" range="-0.400029 0.400029"/>
                    <geom name="L_Wrist" class="smplcontact" size="0.0318 0.0257156" pos="0.042 -0.00405 -0.0075" quat="0.766483 -0.0621494 -0.639251 0" type="capsule"/>
                    <body name="L_Hand" pos="0.084 -0.0082 -0.0149">
                      <joint name="L_Hand_x" pos="0 0 0" axis="1 0 0" range="-0.300022 0.300022"/>
                      <joint name="L_Hand_y" pos="0 0 0" axis="0 1 0" range="-0.900066 0.900066"/>
                      <joint name="L_Hand_z" pos="0 0 0" axis="0 0 1" range="-1.59994 1.59994"/>
                      <geom name="L_Hand" class="smplcontact" size="0.0585 0.0158 0.0538" pos="0.0493 0.001 -0.0058" type="box" density="400.553"/>
                    </body>
                  </body>
                </body>
              </body>
            </body>
            <body name="R_Thorax" pos="-0.0818 0.1188 -0.0386">
              <joint name="R_Thorax_x" class="stiff_medium_higher" pos="0 0 0" axis="1 0 0" range="-0.190066 0.0799361" damping="20"/>
              <joint name="R_Thorax_y" class="stiff_medium_higher" pos="0 0 0" axis="0 1 0" range="-0.300022 0.500037" damping="20"/>
              <joint name="R_Thorax_z" class="stiff_medium_higher" pos="0 0 0" axis="0 0 1" range="-0.700052 0.549953" damping="20"/>
              <geom name="R_Thorax" size="0.0511 0.0305297" pos="-0.048 0.01625 -0.00455" quat="0.738267 0.216291 0.63889 0" type="capsule"/>
              <body name="R_Shoulder" pos="-0.096 0.0326 -0.0091">
                <joint name="R_Shoulder_x" class="stiff_medium" pos="0 0 0" axis="1 0 0" range="-1.69995 1.69995" damping="6"/>
                <joint name="R_Shoulder_y" class="stiff_medium" pos="0 0 0" axis="0 1 0" range="-1.39993 1.89997" damping="6"/>
                <joint name="R_Shoulder_z" class="stiff_medium" pos="0 0 0" axis="0 0 1" range="-1.49994 1.69995" damping="6"/>
                <geom name="R_Shoulder" size="0.0531 0.0765231" pos="-0.12685 -0.0067 -0.0107" quat="0.736082 -0.0355068 0.67596 0" type="capsule"/>
                <body name="R_Elbow" pos="-0.2537 -0.0133 -0.0214">
                  <joint name="R_Elbow_x" pos="0 0 0" axis="1 0 0" range="-0.300022 0.0799361" damping="5"/>
                  <joint name="R_Elbow_y" pos="0 0 0" axis="0 1 0" range="-0.300022 3.14159" damping="5"/>
                  <joint name="R_Elbow_z" pos="0 0 0" axis="0 0 1" range="-0.0799361 1.75999" damping="5"/>
                  <geom name="R_Elbow" size="0.0408 0.0766023" pos="-0.12765 0.0039 -0.00275" quat="0.714682 0.021006 0.699134 0" type="capsule"/>
                  <body name="R_Wrist" pos="-0.2553 0.0078 -0.0056">
                    <joint name="R_Wrist_x" pos="0 0 0" axis="1 0 0" range="-3.14159 0.400029"/>
                    <joint name="R_Wrist_y" pos="0 0 0" axis="0 1 0" range="-0.300022 0.300022"/>
                    <joint name="R_Wrist_z" pos="0 0 0" axis="0 0 1" range="-0.400029 0.400029"/>
                    <geom name="R_Wrist" class="smplcontact" size="0.0326 0.0256553" pos="-0.0423 -0.00305 -0.0052" quat="0.74861 -0.0481626 0.661259 0" type="capsule"/>
                    <body name="R_Hand" pos="-0.0846 -0.0061 -0.0103">
                      <joint name="R_Hand_x" pos="0 0 0" axis="1 0 0" range="-0.300022 0.300022"/>
                      <joint name="R_Hand_y" pos="0 0 0" axis="0 1 0" range="-0.900066 0.900066"/>
                      <joint name="R_Hand_z" pos="0 0 0" axis="0 0 1" range="-1.59994 1.59994"/>
                      <geom name="R_Hand" class="smplcontact" size="0.0569 0.0164 0.0546" pos="-0.0462 -0.0009 -0.0079" type="box" density="403.68"/>
                    </body>
                  </body>
                </body>
              </body>
            </body>
          </body>
        </body>
      </body>
    </body>
  </worldbody>

  <contact>
    <exclude body1="L_Knee" body2="L_Toe"/>
    <exclude body1="L_Knee" body2="R_Ankle"/>
    <exclude body1="L_Knee" body2="R_Toe"/>
    <exclude body1="L_Ankle" body2="R_Knee"/>
    <exclude body1="L_Toe" body2="R_Knee"/>
    <exclude body1="R_Knee" body2="R_Toe"/>
    <exclude body1="Torso" body2="Chest"/>
    <exclude body1="Chest" body2="Head"/>
    <exclude body1="Chest" body2="L_Shoulder"/>
    <exclude body1="Chest" body2="R_Shoulder"/>
  </contact>

  <actuator>
    <general name="L_Hip_x" joint="L_Hip_x" ctrllimited="true" ctrlrange="-1 1" forcerange="-360 360" biastype="affine" gainprm="287.33" biasprm="-215.325 -180 -2"/>
    <general name="L_Hip_y" joint="L_Hip_y" ctrllimited="true" ctrlrange="-1 1" forcerange="-360 360" biastype="affine" gainprm="219.911" biasprm="0 -180 -2"/>
    <general name="L_Hip_z" joint="L_Hip_z" ctrllimited="true" ctrlrange="-1 1" forcerange="-360 360" biastype="affine" gainprm="186.375" biasprm="96.3684 -180 -2"/>
    <general name="L_Knee_x" joint="L_Knee_x" ctrllimited="true" ctrlrange="-1 1" forcerange="-360 360" biastype="affine" gainprm="278.109" biasprm="261.899 -180 -2"/>
    <general name="L_Knee_y" joint="L_Knee_y" ctrllimited="true" ctrlrange="-1 1" forcerange="-360 360" biastype="affine" gainprm="18.0013" biasprm="3.61283 -180 -2"/>
    <general name="L_Knee_z" joint="L_Knee_z" ctrllimited="true" ctrlrange="-1 1" forcerange="-360 360" biastype="affine" gainprm="18.0013" biasprm="-3.61283 -180 -2"/>
    <general name="L_Ankle_x" joint="L_Ankle_x" ctrllimited="true" ctrlrange="-1 1" forcerange="-180 180" biastype="affine" gainprm="72.0053" biasprm="0 -90 -2"/>
    <general name="L_Ankle_y" joint="L_Ankle_y" ctrllimited="true" ctrlrange="-1 1" forcerange="-180 180" biastype="affine" gainprm="76.4978" biasprm="-40.4951 -90 -2"/>
    <general name="L_Ankle_z" joint="L_Ankle_z" ctrllimited="true" ctrlrange="-1 1" forcerange="-180 180" biastype="affine" gainprm="7.19425" biasprm="0 -90 -2"/>
    <general name="L_Toe_x" joint="L_Toe_x" ctrllimited="true" ctrlrange="-1 1" forcerange="-144 144" biastype="affine" gainprm="71.999" biasprm="-43.1969 -72 -0.8"/>
    <general name="L_Toe_y" joint="L_Toe_y" ctrllimited="true" ctrlrange="-1 1" forcerange="-144 144" biastype="affine" gainprm="5.7554" biasprm="0 -72 -0.8"/>
    <general name="L_Toe_z" joint="L_Toe_z" ctrllimited="true" ctrlrange="-1 1" forcerange="-144 144" biastype="affine" gainprm="5.7554" biasprm="0 -72 -0.8"/>
    <general name="R_Hip_x" joint="R_Hip_x" ctrllimited="true" ctrlrange="-1 1" forcerange="-360 360" biastype="affine" gainprm="287.33" biasprm="-215.325 -180 -2"/>
    <general name="R_Hip_y" joint="R_Hip_y" ctrllimited="true" ctrlrange="-1 1" forcerange="-360 360" biastype="affine" gainprm="219.911" biasprm="0 -180 -2"/>
    <general name="R_Hip_z" joint="R_Hip_z" ctrllimited="true" ctrlrange="-1 1" forcerange="-360 360" biastype="affine" gainprm="186.375" biasprm="-96.3684 -180 -2"/>
    <general name="R_Knee_x" joint="R_Knee_x" ctrllimited="true" ctrlrange="-1 1" forcerange="-360 360" biastype="affine" gainprm="278.109" biasprm="261.899 -180 -2"/>
    <general name="R_Knee_y" joint="R_Knee_y" ctrllimited="true" ctrlrange="-1 1" forcerange="-360 360" biastype="affine" gainprm="18.0013" biasprm="-3.61283 -180 -2"/>
    <general name="R_Knee_z" joint="R_Knee_z" ctrllimited="true" ctrlrange="-1 1" forcerange="-360 360" biastype="affine" gainprm="18.0013" biasprm="3.61283 -180 -2"/>
    <general name="R_Ankle_x" joint="R_Ankle_x" ctrllimited="true" ctrlrange="-1 1" forcerange="-180 180" biastype="affine" gainprm="72.0053" biasprm="0 -90 -2"/>
    <general name="R_Ankle_y" joint="R_Ankle_y" ctrllimited="true" ctrlrange="-1 1" forcerange="-180 180" biastype="affine" gainprm="76.4978" biasprm="40.4951 -90 -2"/>
    <general name="R_Ankle_z" joint="R_Ankle_z" ctrllimited="true" ctrlrange="-1 1" forcerange="-180 180" biastype="affine" gainprm="7.19425" biasprm="0 -90 -2"/>
    <general name="R_Toe_x" joint="R_Toe_x" ctrllimited="true" ctrlrange="-1 1" forcerange="-144 144" biastype="affine" gainprm="71.999" biasprm="-43.1969 -72 -0.8"/>
    <general name="R_Toe_y" joint="R_Toe_y" ctrllimited="true" ctrlrange="-1 1" forcerange="-144 144" biastype="affine" gainprm="5.7554" biasprm="0 -72 -0.8"/>
    <general name="R_Toe_z" joint="R_Toe_z" ctrllimited="true" ctrlrange="-1 1" forcerange="-144 144" biastype="affine" gainprm="5.7554" biasprm="0 -72 -0.8"/>
    <general name="Torso_x" joint="Torso_x" ctrllimited="true" ctrlrange="-1 1" forcerange="-360 360" biastype="affine" gainprm="174.002" biasprm="66.0153 -240 -4"/>
    <general name="Torso_y" joint="Torso_y" ctrllimited="true" ctrlrange="-1 1" forcerange="-360 360" biastype="affine" gainprm="240.018" biasprm="0 -240 -4"/>
    <general name="Torso_z" joint="Torso_z" ctrllimited="true" ctrlrange="-1 1" forcerange="-360 360" biastype="affine" gainprm="144.011" biasprm="0 -240 -4"/>
    <general name="Spine_x" joint="Spine_x" ctrllimited="true" ctrlrange="-1 1" forcerange="-360 360" biastype="affine" gainprm="174.002" biasprm="66.0153 -240 -4"/>
    <general name="Spine_y" joint="Spine_y" ctrllimited="true" ctrlrange="-1 1" forcerange="-360 360" biastype="affine" gainprm="240.018" biasprm="0 -240 -4"/>
    <general name="Spine_z" joint="Spine_z" ctrllimited="true" ctrlrange="-1 1" forcerange="-360 360" biastype="affine" gainprm="144.011" biasprm="0 -240 -4"/>
    <general name="Chest_x" joint="Chest_x" ctrllimited="true" ctrlrange="-1 1" forcerange="-360 360" biastype="affine" gainprm="174.002" biasprm="66.0153 -240 -4"/>
    <general name="Chest_y" joint="Chest_y" ctrllimited="true" ctrlrange="-1 1" forcerange="-360 360" biastype="affine" gainprm="240.018" biasprm="0 -240 -4"/>
    <general name="Chest_z" joint="Chest_z" ctrllimited="true" ctrlrange="-1 1" forcerange="-360 360" biastype="affine" gainprm="144.011" biasprm="0 -240 -4"/>
    <general name="Neck_x" joint="Neck_x" ctrllimited="true" ctrlrange="-1 1" forcerange="-72 72" biastype="affine" gainprm="27.002" biasprm="9.00066 -36 -0.8"/>
    <general name="Neck_y" joint="Neck_y" ctrllimited="true" ctrlrange="-1 1" forcerange="-72 72" biastype="affine" gainprm="25.2019" biasprm="0 -36 -0.8"/>
    <general name="Neck_z" joint="Neck_z" ctrllimited="true" ctrlrange="-1 1" forcerange="-72 72" biastype="affine" gainprm="25.2019" biasprm="0 -36 -0.8"/>
    <general name="Head_x" joint="Head_x" ctrllimited="true" ctrlrange="-1 1" forcerange="-48 48" biastype="affine" gainprm="18.0013" biasprm="6.00044 -24 -0.8"/>
    <general name="Head_y" joint="Head_y" ctrllimited="true" ctrlrange="-1 1" forcerange="-48 48" biastype="affine" gainprm="16.8012" biasprm="0 -24 -0.8"/>
    <general name="Head_z" joint="Head_z" ctrllimited="true" ctrlrange="-1 1" forcerange="-48 48" biastype="affine" gainprm="16.8012" biasprm="0 -24 -0.8"/>
    <general name="L_Thorax_x" joint="L_Thorax_x" ctrllimited="true" ctrlrange="-1 1" forcerange="-240 240" biastype="affine" gainprm="16.2001" biasprm="-6.60782 -120 -1.6"/>
    <general name="L_Thorax_y" joint="L_Thorax_y" ctrllimited="true" ctrlrange="-1 1" forcerange="-240 240" biastype="affine" gainprm="48.0035" biasprm="-12.0009 -120 -1.6"/>
    <general name="L_Thorax_z" joint="L_Thorax_z" ctrllimited="true" ctrlrange="-1 1" forcerange="-240 240" biastype="affine" gainprm="75.0003" biasprm="9.0059 -120 -1.6"/>
    <general name="L_Shoulder_x" joint="L_Shoulder_x" ctrllimited="true" ctrlrange="-1 1" forcerange="-96 96" biastype="affine" gainprm="81.5976" biasprm="0 -48 -1.6"/>
    <general name="L_Shoulder_y" joint="L_Shoulder_y" ctrllimited="true" ctrlrange="-1 1" forcerange="-96 96" biastype="affine" gainprm="79.1975" biasprm="-12.0009 -48 -1.6"/>
    <general name="L_Shoulder_z" joint="L_Shoulder_z" ctrllimited="true" ctrlrange="-1 1" forcerange="-96 96" biastype="affine" gainprm="76.7973" biasprm="-4.80035 -48 -1.6"/>
    <general name="L_Elbow_x" joint="L_Elbow_x" ctrllimited="true" ctrlrange="-1 1" forcerange="-144 144" biastype="affine" gainprm="13.6785" biasprm="-7.9231 -72 -0.8"/>
    <general name="L_Elbow_y" joint="L_Elbow_y" ctrllimited="true" ctrlrange="-1 1" forcerange="-144 144" biastype="affine" gainprm="123.898" biasprm="-102.297 -72 -0.8"/>
    <general name="L_Elbow_z" joint="L_Elbow_z" ctrllimited="true" ctrlrange="-1 1" forcerange="-144 144" biastype="affine" gainprm="66.2373" biasprm="-60.4819 -72 -0.8"/>
    <general name="L_Wrist_x" joint="L_Wrist_x" ctrllimited="true" ctrlrange="-1 1" forcerange="-24 24" biastype="affine" gainprm="21.2497" biasprm="-16.4494 -12 -0.8"/>
    <general name="L_Wrist_y" joint="L_Wrist_y" ctrllimited="true" ctrlrange="-1 1" forcerange="-24 24" biastype="affine" gainprm="3.60027" biasprm="0 -12 -0.8"/>
    <general name="L_Wrist_z" joint="L_Wrist_z" ctrllimited="true" ctrlrange="-1 1" forcerange="-24 24" biastype="affine" gainprm="4.80035" biasprm="0 -12 -0.8"/>
    <general name="L_Hand_x" joint="L_Hand_x" ctrllimited="true" ctrlrange="-1 1" forcerange="-24 24" biastype="affine" gainprm="3.60027" biasprm="0 -12 -0.8"/>
    <general name="L_Hand_y" joint="L_Hand_y" ctrllimited="true" ctrlrange="-1 1" forcerange="-24 24" biastype="affine" gainprm="10.8008" biasprm="0 -12 -0.8"/>
    <general name="L_Hand_z" joint="L_Hand_z" ctrllimited="true" ctrlrange="-1 1" forcerange="-24 24" biastype="affine" gainprm="19.1993" biasprm="0 -12 -0.8"/>
    <general name="R_Thorax_x" joint="R_Thorax_x" ctrllimited="true" ctrlrange="-1 1" forcerange="-240 240" biastype="affine" gainprm="16.2001" biasprm="-6.60782 -120 -1.6"/>
    <general name="R_Thorax_y" joint="R_Thorax_y" ctrllimited="true" ctrlrange="-1 1" forcerange="-240 240" biastype="affine" gainprm="48.0035" biasprm="12.0009 -120 -1.6"/>
    <general name="R_Thorax_z" joint="R_Thorax_z" ctrllimited="true" ctrlrange="-1 1" forcerange="-240 240" biastype="affine" gainprm="75.0003" biasprm="-9.0059 -120 -1.6"/>
    <general name="R_Shoulder_x" joint="R_Shoulder_x" ctrllimited="true" ctrlrange="-1 1" forcerange="-96 96" biastype="affine" gainprm="81.5976" biasprm="0 -48 -1.6"/>
    <general name="R_Shoulder_y" joint="R_Shoulder_y" ctrllimited="true" ctrlrange="-1 1" forcerange="-96 96" biastype="affine" gainprm="79.1975" biasprm="12.0009 -48 -1.6"/>
    <general name="R_Shoulder_z" joint="R_Shoulder_z" ctrllimited="true" ctrlrange="-1 1" forcerange="-96 96" biastype="affine" gainprm="76.7973" biasprm="4.80035 -48 -1.6"/>
    <general name="R_Elbow_x" joint="R_Elbow_x" ctrllimited="true" ctrlrange="-1 1" forcerange="-144 144" biastype="affine" gainprm="13.6785" biasprm="-7.9231 -72 -0.8"/>
    <general name="R_Elbow_y" joint="R_Elbow_y" ctrllimited="true" ctrlrange="-1 1" forcerange="-144 144" biastype="affine" gainprm="123.898" biasprm="102.297 -72 -0.8"/>
    <general name="R_Elbow_z" joint="R_Elbow_z" ctrllimited="true" ctrlrange="-1 1" forcerange="-144 144" biastype="affine" gainprm="66.2373" biasprm="60.4819 -72 -0.8"/>
    <general name="R_Wrist_x" joint="R_Wrist_x" ctrllimited="true" ctrlrange="-1 1" forcerange="-24 24" biastype="affine" gainprm="21.2497" biasprm="-16.4494 -12 -0.8"/>
    <general name="R_Wrist_y" joint="R_Wrist_y" ctrllimited="true" ctrlrange="-1 1" forcerange="-24 24" biastype="affine" gainprm="3.60027" biasprm="0 -12 -0.8"/>
    <general name="R_Wrist_z" joint="R_Wrist_z" ctrllimited="true" ctrlrange="-1 1" forcerange="-24 24" biastype="affine" gainprm="4.80035" biasprm="0 -12 -0.8"/>
    <general name="R_Hand_x" joint="R_Hand_x" ctrllimited="true" ctrlrange="-1 1" forcerange="-24 24" biastype="affine" gainprm="3.60027" biasprm="0 -12 -0.8"/>
    <general name="R_Hand_y" joint="R_Hand_y" ctrllimited="true" ctrlrange="-1 1" forcerange="-24 24" biastype="affine" gainprm="10.8008" biasprm="0 -12 -0.8"/>
    <general name="R_Hand_z" joint="R_Hand_z" ctrllimited="true" ctrlrange="-1 1" forcerange="-24 24" biastype="affine" gainprm="19.1993" biasprm="0 -12 -0.8"/>
  </actuator>

  <sensor>
    <framelinvel objtype="xbody" objname="Pelvis" name="sensor_Pelvis_framelinvel"/>
    <framelinvel objtype="xbody" objname="L_Hip" name="sensor_L_Hip_framelinvel"/>
    <framelinvel objtype="xbody" objname="L_Knee" name="sensor_L_Knee_framelinvel"/>
    <framelinvel objtype="xbody" objname="L_Ankle" name="sensor_L_Ankle_framelinvel"/>
    <framelinvel objtype="xbody" objname="L_Toe" name="sensor_L_Toe_framelinvel"/>
    <framelinvel objtype="xbody" objname="R_Hip" name="sensor_R_Hip_framelinvel"/>
    <framelinvel objtype="xbody" objname="R_Knee" name="sensor_R_Knee_framelinvel"/>
    <framelinvel objtype="xbody" objname="R_Ankle" name="sensor_R_Ankle_framelinvel"/>
    <framelinvel objtype="xbody" objname="R_Toe" name="sensor_R_Toe_framelinvel"/>
    <framelinvel objtype="xbody" objname="Torso" name="sensor_Torso_framelinvel"/>
    <framelinvel objtype="xbody" objname="Spine" name="sensor_Spine_framelinvel"/>
    <framelinvel objtype="xbody" objname="Chest" name="sensor_Chest_framelinvel"/>
    <framelinvel objtype="xbody" objname="Neck" name="sensor_Neck_framelinvel"/>
    <framelinvel objtype="xbody" objname="Head" name="sensor_Head_framelinvel"/>
    <framelinvel objtype="xbody" objname="L_Thorax" name="sensor_L_Thorax_framelinvel"/>
    <framelinvel objtype="xbody" objname="L_Shoulder" name="sensor_L_Shoulder_framelinvel"/>
    <framelinvel objtype="xbody" objname="L_Elbow" name="sensor_L_Elbow_framelinvel"/>
    <framelinvel objtype="xbody" objname="L_Wrist" name="sensor_L_Wrist_framelinvel"/>
    <framelinvel objtype="xbody" objname="L_Hand" name="sensor_L_Hand_framelinvel"/>
    <framelinvel objtype="xbody" objname="R_Thorax" name="sensor_R_Thorax_framelinvel"/>
    <framelinvel objtype="xbody" objname="R_Shoulder" name="sensor_R_Shoulder_framelinvel"/>
    <framelinvel objtype="xbody" objname="R_Elbow" name="sensor_R_Elbow_framelinvel"/>
    <framelinvel objtype="xbody" objname="R_Wrist" name="sensor_R_Wrist_framelinvel"/>
    <framelinvel objtype="xbody" objname="R_Hand" name="sensor_R_Hand_framelinvel"/>
    <frameangvel objtype="xbody" objname="Pelvis" name="sensor_Pelvis_frameangvel"/>
    <frameangvel objtype="xbody" objname="L_Hip" name="sensor_L_Hip_frameangvel"/>
    <frameangvel objtype="xbody" objname="L_Knee" name="sensor_L_Knee_frameangvel"/>
    <frameangvel objtype="xbody" objname="L_Ankle" name="sensor_L_Ankle_frameangvel"/>
    <frameangvel objtype="xbody" objname="L_Toe" name="sensor_L_Toe_frameangvel"/>
    <frameangvel objtype="xbody" objname="R_Hip" name="sensor_R_Hip_frameangvel"/>
    <frameangvel objtype="xbody" objname="R_Knee" name="sensor_R_Knee_frameangvel"/>
    <frameangvel objtype="xbody" objname="R_Ankle" name="sensor_R_Ankle_frameangvel"/>
    <frameangvel objtype="xbody" objname="R_Toe" name="sensor_R_Toe_frameangvel"/>
    <frameangvel objtype="xbody" objname="Torso" name="sensor_Torso_frameangvel"/>
    <frameangvel objtype="xbody" objname="Spine" name="sensor_Spine_frameangvel"/>
    <frameangvel objtype="xbody" objname="Chest" name="sensor_Chest_frameangvel"/>
    <frameangvel objtype="xbody" objname="Neck" name="sensor_Neck_frameangvel"/>
    <frameangvel objtype="xbody" objname="Head" name="sensor_Head_frameangvel"/>
    <frameangvel objtype="xbody" objname="L_Thorax" name="sensor_L_Thorax_frameangvel"/>
    <frameangvel objtype="xbody" objname="L_Shoulder" name="sensor_L_Shoulder_frameangvel"/>
    <frameangvel objtype="xbody" objname="L_Elbow" name="sensor_L_Elbow_frameangvel"/>
    <frameangvel objtype="xbody" objname="L_Wrist" name="sensor_L_Wrist_frameangvel"/>
    <frameangvel objtype="xbody" objname="L_Hand" name="sensor_L_Hand_frameangvel"/>
    <frameangvel objtype="xbody" objname="R_Thorax" name="sensor_R_Thorax_frameangvel"/>
    <frameangvel objtype="xbody" objname="R_Shoulder" name="sensor_R_Shoulder_frameangvel"/>
    <frameangvel objtype="xbody" objname="R_Elbow" name="sensor_R_Elbow_frameangvel"/>
    <frameangvel objtype="xbody" objname="R_Wrist" name="sensor_R_Wrist_frameangvel"/>
    <frameangvel objtype="xbody" objname="R_Hand" name="sensor_R_Hand_frameangvel"/>
    <subtreelinvel body="Chest" name="Chest_subtreelinvel"/>
    <gyro site="Pelvis" name="Pelvis_gyro"/>
  </sensor>
</mujoco>
